#[
ValueError
Traceback:
    from errorfunc.lly:1: in f
    from use_errorfunc.lly:10: in __main__
]#

import errorfunc

errorfunc::f()
